[2025-07-22T11:49:58.859+0000] {taskinstance.py:1956} INFO - Dependencies all met for dep_context=non-requeueable deps ti=<TaskInstance: banking_checking.run_script_over_ssh manual__2025-07-22T11:49:58.079819+00:00 [queued]>
[2025-07-22T11:49:58.869+0000] {taskinstance.py:1956} INFO - Dependencies all met for dep_context=requeueable deps ti=<TaskInstance: banking_checking.run_script_over_ssh manual__2025-07-22T11:49:58.079819+00:00 [queued]>
[2025-07-22T11:49:58.870+0000] {taskinstance.py:2170} INFO - Starting attempt 1 of 1
[2025-07-22T11:49:58.881+0000] {taskinstance.py:2191} INFO - Executing <Task(SSHOperator): run_script_over_ssh> on 2025-07-22 11:49:58.079819+00:00
[2025-07-22T11:49:58.885+0000] {standard_task_runner.py:60} INFO - Started process 398 to run task
[2025-07-22T11:49:58.887+0000] {standard_task_runner.py:87} INFO - Running: ['***', 'tasks', 'run', 'banking_checking', 'run_script_over_ssh', 'manual__2025-07-22T11:49:58.079819+00:00', '--job-id', '2', '--raw', '--subdir', 'DAGS_FOLDER/banking_checking.py', '--cfg-path', '/tmp/tmpjtafjpz1']
[2025-07-22T11:49:58.889+0000] {standard_task_runner.py:88} INFO - Job 2: Subtask run_script_over_ssh
[2025-07-22T11:49:58.933+0000] {task_command.py:423} INFO - Running <TaskInstance: banking_checking.run_script_over_ssh manual__2025-07-22T11:49:58.079819+00:00 [running]> on host f8d6997bd320
[2025-07-22T11:49:58.999+0000] {taskinstance.py:2480} INFO - Exporting env vars: AIRFLOW_CTX_DAG_OWNER='***' AIRFLOW_CTX_DAG_ID='banking_checking' AIRFLOW_CTX_TASK_ID='run_script_over_ssh' AIRFLOW_CTX_EXECUTION_DATE='2025-07-22T11:49:58.079819+00:00' AIRFLOW_CTX_TRY_NUMBER='1' AIRFLOW_CTX_DAG_RUN_ID='manual__2025-07-22T11:49:58.079819+00:00'
[2025-07-22T11:49:59.000+0000] {ssh.py:152} INFO - Creating ssh_client
[2025-07-22T11:49:59.001+0000] {ssh.py:125} INFO - ssh_hook is not provided or invalid. Trying ssh_conn_id to create SSHHook.
[2025-07-22T11:49:59.004+0000] {base.py:83} INFO - Using connection ID 'ssh_python_service' for task execution.
[2025-07-22T11:49:59.005+0000] {ssh.py:300} WARNING - No Host Key Verification. This won't protect against Man-In-The-Middle attacks
[2025-07-22T11:49:59.016+0000] {transport.py:1909} INFO - Connected (version 2.0, client OpenSSH_9.2p1)
[2025-07-22T11:49:59.105+0000] {transport.py:1909} INFO - Authentication (password) successful!
[2025-07-22T11:49:59.106+0000] {ssh.py:478} INFO - Running command: python /app/generate_data.py
[2025-07-22T11:49:59.486+0000] {ssh.py:529} WARNING - Traceback (most recent call last):
[2025-07-22T11:49:59.487+0000] {ssh.py:529} WARNING -   File "/usr/local/lib/python3.10/site-packages/sqlalchemy/engine/base.py", line 145, in __init__
[2025-07-22T11:49:59.487+0000] {ssh.py:529} WARNING -     self._dbapi_connection = engine.raw_connection()
[2025-07-22T11:49:59.488+0000] {ssh.py:529} WARNING -   File "/usr/local/lib/python3.10/site-packages/sqlalchemy/engine/base.py", line 3288, in raw_connection
[2025-07-22T11:49:59.489+0000] {ssh.py:529} WARNING -     return self.pool.connect()
[2025-07-22T11:49:59.489+0000] {ssh.py:529} WARNING -   File "/usr/local/lib/python3.10/site-packages/sqlalchemy/pool/base.py", line 452, in connect
[2025-07-22T11:49:59.489+0000] {ssh.py:529} WARNING -     return _ConnectionFairy._checkout(self)
[2025-07-22T11:49:59.490+0000] {ssh.py:529} WARNING -   File "/usr/local/lib/python3.10/site-packages/sqlalchemy/pool/base.py", line 1267, in _checkout
[2025-07-22T11:49:59.490+0000] {ssh.py:529} WARNING -     fairy = _ConnectionRecord.checkout(pool)
[2025-07-22T11:49:59.490+0000] {ssh.py:529} WARNING -   File "/usr/local/lib/python3.10/site-packages/sqlalchemy/pool/base.py", line 716, in checkout
[2025-07-22T11:49:59.491+0000] {ssh.py:529} WARNING -     rec = pool._do_get()
[2025-07-22T11:49:59.492+0000] {ssh.py:529} WARNING -   File "/usr/local/lib/python3.10/site-packages/sqlalchemy/pool/impl.py", line 169, in _do_get
[2025-07-22T11:49:59.492+0000] {ssh.py:529} WARNING -     with util.safe_reraise():
[2025-07-22T11:49:59.493+0000] {ssh.py:529} WARNING -   File "/usr/local/lib/python3.10/site-packages/sqlalchemy/util/langhelpers.py", line 147, in __exit__
[2025-07-22T11:49:59.493+0000] {ssh.py:529} WARNING -     raise exc_value.with_traceback(exc_tb)
[2025-07-22T11:49:59.494+0000] {ssh.py:529} WARNING -   File "/usr/local/lib/python3.10/site-packages/sqlalchemy/pool/impl.py", line 167, in _do_get
[2025-07-22T11:49:59.494+0000] {ssh.py:529} WARNING -     return self._create_connection()
[2025-07-22T11:49:59.496+0000] {ssh.py:529} WARNING -   File "/usr/local/lib/python3.10/site-packages/sqlalchemy/pool/base.py", line 393, in _create_connection
[2025-07-22T11:49:59.496+0000] {ssh.py:529} WARNING -     return _ConnectionRecord(self)
[2025-07-22T11:49:59.496+0000] {ssh.py:529} WARNING -   File "/usr/local/lib/python3.10/site-packages/sqlalchemy/pool/base.py", line 678, in __init__
[2025-07-22T11:49:59.496+0000] {ssh.py:529} WARNING -     self.__connect()
[2025-07-22T11:49:59.497+0000] {ssh.py:529} WARNING -   File "/usr/local/lib/python3.10/site-packages/sqlalchemy/pool/base.py", line 902, in __connect
[2025-07-22T11:49:59.497+0000] {ssh.py:529} WARNING -     with util.safe_reraise():
[2025-07-22T11:49:59.497+0000] {ssh.py:529} WARNING -   File "/usr/local/lib/python3.10/site-packages/sqlalchemy/util/langhelpers.py", line 147, in __exit__
[2025-07-22T11:49:59.497+0000] {ssh.py:529} WARNING -     raise exc_value.with_traceback(exc_tb)
[2025-07-22T11:49:59.498+0000] {ssh.py:529} WARNING -   File "/usr/local/lib/python3.10/site-packages/sqlalchemy/pool/base.py", line 898, in __connect
[2025-07-22T11:49:59.498+0000] {ssh.py:529} WARNING -     self.dbapi_connection = connection = pool._invoke_creator(self)
[2025-07-22T11:49:59.498+0000] {ssh.py:529} WARNING -   File "/usr/local/lib/python3.10/site-packages/sqlalchemy/engine/create.py", line 637, in connect
[2025-07-22T11:49:59.498+0000] {ssh.py:529} WARNING -     return dialect.connect(*cargs, **cparams)
[2025-07-22T11:49:59.499+0000] {ssh.py:529} WARNING -   File "/usr/local/lib/python3.10/site-packages/sqlalchemy/engine/default.py", line 615, in connect
[2025-07-22T11:49:59.500+0000] {ssh.py:529} WARNING -     return self.loaded_dbapi.connect(*cargs, **cparams)
[2025-07-22T11:49:59.500+0000] {ssh.py:529} WARNING - sqlite3.OperationalError: unable to open database file
[2025-07-22T11:49:59.500+0000] {ssh.py:529} WARNING - 
[2025-07-22T11:49:59.501+0000] {ssh.py:529} WARNING - The above exception was the direct cause of the following exception:
[2025-07-22T11:49:59.501+0000] {ssh.py:529} WARNING - 
[2025-07-22T11:49:59.502+0000] {ssh.py:529} WARNING - Traceback (most recent call last):
[2025-07-22T11:49:59.502+0000] {ssh.py:529} WARNING -   File "/app/generate_data.py", line 21, in <module>
[2025-07-22T11:49:59.502+0000] {ssh.py:529} WARNING -     Base.metadata.create_all(engine)
[2025-07-22T11:49:59.502+0000] {ssh.py:529} WARNING -   File "/usr/local/lib/python3.10/site-packages/sqlalchemy/sql/schema.py", line 5822, in create_all
[2025-07-22T11:49:59.502+0000] {ssh.py:529} WARNING -     bind._run_ddl_visitor(
[2025-07-22T11:49:59.504+0000] {ssh.py:529} WARNING -   File "/usr/local/lib/python3.10/site-packages/sqlalchemy/engine/base.py", line 3238, in _run_ddl_visitor
[2025-07-22T11:49:59.504+0000] {ssh.py:529} WARNING -     with self.begin() as conn:
[2025-07-22T11:49:59.504+0000] {ssh.py:529} WARNING -   File "/usr/local/lib/python3.10/contextlib.py", line 135, in __enter__
[2025-07-22T11:49:59.504+0000] {ssh.py:529} WARNING -     return next(self.gen)
[2025-07-22T11:49:59.505+0000] {ssh.py:529} WARNING -   File "/usr/local/lib/python3.10/site-packages/sqlalchemy/engine/base.py", line 3228, in begin
[2025-07-22T11:49:59.505+0000] {ssh.py:529} WARNING -     with self.connect() as conn:
[2025-07-22T11:49:59.505+0000] {ssh.py:529} WARNING -   File "/usr/local/lib/python3.10/site-packages/sqlalchemy/engine/base.py", line 3264, in connect
[2025-07-22T11:49:59.505+0000] {ssh.py:529} WARNING -     return self._connection_cls(self)
[2025-07-22T11:49:59.505+0000] {ssh.py:529} WARNING -   File "/usr/local/lib/python3.10/site-packages/sqlalchemy/engine/base.py", line 147, in __init__
[2025-07-22T11:49:59.505+0000] {ssh.py:529} WARNING -     Connection._handle_dbapi_exception_noconnection(
[2025-07-22T11:49:59.505+0000] {ssh.py:529} WARNING -   File "/usr/local/lib/python3.10/site-packages/sqlalchemy/engine/base.py", line 2426, in _handle_dbapi_exception_noconnection
[2025-07-22T11:49:59.506+0000] {ssh.py:529} WARNING -     raise sqlalchemy_exception.with_traceback(exc_info[2]) from e
[2025-07-22T11:49:59.506+0000] {ssh.py:529} WARNING -   File "/usr/local/lib/python3.10/site-packages/sqlalchemy/engine/base.py", line 145, in __init__
[2025-07-22T11:49:59.507+0000] {ssh.py:529} WARNING -     self._dbapi_connection = engine.raw_connection()
[2025-07-22T11:49:59.507+0000] {ssh.py:529} WARNING -   File "/usr/local/lib/python3.10/site-packages/sqlalchemy/engine/base.py", line 3288, in raw_connection
[2025-07-22T11:49:59.507+0000] {ssh.py:529} WARNING -     return self.pool.connect()
[2025-07-22T11:49:59.508+0000] {ssh.py:529} WARNING -   File "/usr/local/lib/python3.10/site-packages/sqlalchemy/pool/base.py", line 452, in connect
[2025-07-22T11:49:59.508+0000] {ssh.py:529} WARNING -     return _ConnectionFairy._checkout(self)
[2025-07-22T11:49:59.508+0000] {ssh.py:529} WARNING -   File "/usr/local/lib/python3.10/site-packages/sqlalchemy/pool/base.py", line 1267, in _checkout
[2025-07-22T11:49:59.509+0000] {ssh.py:529} WARNING -     fairy = _ConnectionRecord.checkout(pool)
[2025-07-22T11:49:59.510+0000] {ssh.py:529} WARNING -   File "/usr/local/lib/python3.10/site-packages/sqlalchemy/pool/base.py", line 716, in checkout
[2025-07-22T11:49:59.510+0000] {ssh.py:529} WARNING -     rec = pool._do_get()
[2025-07-22T11:49:59.510+0000] {ssh.py:529} WARNING -   File "/usr/local/lib/python3.10/site-packages/sqlalchemy/pool/impl.py", line 169, in _do_get
[2025-07-22T11:49:59.510+0000] {ssh.py:529} WARNING -     with util.safe_reraise():
[2025-07-22T11:49:59.510+0000] {ssh.py:529} WARNING -   File "/usr/local/lib/python3.10/site-packages/sqlalchemy/util/langhelpers.py", line 147, in __exit__
[2025-07-22T11:49:59.511+0000] {ssh.py:529} WARNING -     raise exc_value.with_traceback(exc_tb)
[2025-07-22T11:49:59.512+0000] {ssh.py:529} WARNING -   File "/usr/local/lib/python3.10/site-packages/sqlalchemy/pool/impl.py", line 167, in _do_get
[2025-07-22T11:49:59.512+0000] {ssh.py:529} WARNING -     return self._create_connection()
[2025-07-22T11:49:59.512+0000] {ssh.py:529} WARNING -   File "/usr/local/lib/python3.10/site-packages/sqlalchemy/pool/base.py", line 393, in _create_connection
[2025-07-22T11:49:59.512+0000] {ssh.py:529} WARNING -     return _ConnectionRecord(self)
[2025-07-22T11:49:59.512+0000] {ssh.py:529} WARNING -   File "/usr/local/lib/python3.10/site-packages/sqlalchemy/pool/base.py", line 678, in __init__
[2025-07-22T11:49:59.513+0000] {ssh.py:529} WARNING -     self.__connect()
[2025-07-22T11:49:59.514+0000] {ssh.py:529} WARNING -   File "/usr/local/lib/python3.10/site-packages/sqlalchemy/pool/base.py", line 902, in __connect
[2025-07-22T11:49:59.514+0000] {ssh.py:529} WARNING -     with util.safe_reraise():
[2025-07-22T11:49:59.514+0000] {ssh.py:529} WARNING -   File "/usr/local/lib/python3.10/site-packages/sqlalchemy/util/langhelpers.py", line 147, in __exit__
[2025-07-22T11:49:59.515+0000] {ssh.py:529} WARNING -     raise exc_value.with_traceback(exc_tb)
[2025-07-22T11:49:59.515+0000] {ssh.py:529} WARNING -   File "/usr/local/lib/python3.10/site-packages/sqlalchemy/pool/base.py", line 898, in __connect
[2025-07-22T11:49:59.515+0000] {ssh.py:529} WARNING -     self.dbapi_connection = connection = pool._invoke_creator(self)
[2025-07-22T11:49:59.515+0000] {ssh.py:529} WARNING -   File "/usr/local/lib/python3.10/site-packages/sqlalchemy/engine/create.py", line 637, in connect
[2025-07-22T11:49:59.515+0000] {ssh.py:529} WARNING -     return dialect.connect(*cargs, **cparams)
[2025-07-22T11:49:59.516+0000] {ssh.py:529} WARNING -   File "/usr/local/lib/python3.10/site-packages/sqlalchemy/engine/default.py", line 615, in connect
[2025-07-22T11:49:59.516+0000] {ssh.py:529} WARNING -     return self.loaded_dbapi.connect(*cargs, **cparams)
[2025-07-22T11:49:59.516+0000] {ssh.py:529} WARNING - sqlalchemy.exc.OperationalError: (sqlite3.OperationalError) unable to open database file
[2025-07-22T11:49:59.516+0000] {ssh.py:529} WARNING - (Background on this error at: https://sqlalche.me/e/20/e3q8)
[2025-07-22T11:49:59.571+0000] {taskinstance.py:2698} ERROR - Task failed with exception
Traceback (most recent call last):
  File "/home/airflow/.local/lib/python3.8/site-packages/airflow/models/taskinstance.py", line 433, in _execute_task
    result = execute_callable(context=context, **execute_callable_kwargs)
  File "/home/airflow/.local/lib/python3.8/site-packages/airflow/providers/ssh/operators/ssh.py", line 191, in execute
    result = self.run_ssh_client_command(ssh_client, self.command, context=context)
  File "/home/airflow/.local/lib/python3.8/site-packages/airflow/providers/ssh/operators/ssh.py", line 179, in run_ssh_client_command
    self.raise_for_status(exit_status, agg_stderr, context=context)
  File "/home/airflow/.local/lib/python3.8/site-packages/airflow/providers/ssh/operators/ssh.py", line 173, in raise_for_status
    raise AirflowException(f"SSH operator error: exit status = {exit_status}")
airflow.exceptions.AirflowException: SSH operator error: exit status = 1
[2025-07-22T11:49:59.573+0000] {taskinstance.py:1138} INFO - Marking task as FAILED. dag_id=banking_checking, task_id=run_script_over_ssh, execution_date=20250722T114958, start_date=20250722T114958, end_date=20250722T114959
[2025-07-22T11:49:59.582+0000] {standard_task_runner.py:107} ERROR - Failed to execute job 2 for task run_script_over_ssh (SSH operator error: exit status = 1; 398)
[2025-07-22T11:49:59.599+0000] {local_task_job_runner.py:234} INFO - Task exited with return code 1
[2025-07-22T11:49:59.611+0000] {taskinstance.py:3280} INFO - 0 downstream tasks scheduled from follow-on schedule check
